Workbook
Name alpha: data!$D$4:$D$19
Name avgError: data!$I$4:$I$19
Name avgITLError: data!$H$4:$H$19
Name avgTTFTError: data!$G$4:$G$19
Name beta: data!$E$4:$E$19
Name gamma: data!$F$4:$F$19
Name inTokens: data!$B$4:$B$19
Name outTokens: data!$C$4:$C$19
Name table: data!$B$4:$I$19

Sheet main
B2: alpha
E3: outTokens
D4: 64 | E4: 256 | F4: 1024 | G4: 4096
C5: 64 | D5: {=_xlfn.XLOOKUP($C5&D$4,inTokens&outTokens,alpha)} -> 6.027926 | E5: {=_xlfn.XLOOKUP($C5&E$4,inTokens&outTokens,alpha)} -> 6.016698 | F5: {=_xlfn.XLOOKUP($C5&F$4,inTokens&outTokens,alpha)} -> 6.000024 | G5: {=_xlfn.XLOOKUP($C5&G$4,inTokens&outTokens,alpha)} -> 6.098779
B6: inTokens | C6: 256 | D6: {=_xlfn.XLOOKUP($C6&D$4,inTokens&outTokens,alpha)} -> 6.029422 | E6: {=_xlfn.XLOOKUP($C6&E$4,inTokens&outTokens,alpha)} -> 6.014978 | F6: {=_xlfn.XLOOKUP($C6&F$4,inTokens&outTokens,alpha)} -> 6.016668 | G6: {=_xlfn.XLOOKUP($C6&G$4,inTokens&outTokens,alpha)} -> 6.000054
C7: 1024 | D7: {=_xlfn.XLOOKUP($C7&D$4,inTokens&outTokens,alpha)} -> 6.025469 | E7: {=_xlfn.XLOOKUP($C7&E$4,inTokens&outTokens,alpha)} -> 6.026902 | F7: {=_xlfn.XLOOKUP($C7&F$4,inTokens&outTokens,alpha)} -> 6.016738 | G7: {=_xlfn.XLOOKUP($C7&G$4,inTokens&outTokens,alpha)} -> 6.008825
C8: 4096 | D8: {=_xlfn.XLOOKUP($C8&D$4,inTokens&outTokens,alpha)} -> 6.027918 | E8: {=_xlfn.XLOOKUP($C8&E$4,inTokens&outTokens,alpha)} -> 6.026099 | F8: {=_xlfn.XLOOKUP($C8&F$4,inTokens&outTokens,alpha)} -> 6.023934 | G8: {=_xlfn.XLOOKUP($C8&G$4,inTokens&outTokens,alpha)} -> 6.023698
B17: beta
E18: =E3 -> outTokens
D19: =D4 -> 64 | E19: =E4 -> 256 | F19: =F4 -> 1024 | G19: =G4 -> 4096
C20: =C5 -> 64 | D20: {=_xlfn.XLOOKUP($C20&D$19,inTokens&outTokens,beta)} -> 0.022009101 | E20: {=_xlfn.XLOOKUP($C20&E$19,inTokens&outTokens,beta)} -> 0.033311078 | F20: {=_xlfn.XLOOKUP($C20&F$19,inTokens&outTokens,beta)} -> 0.049968896 | G20: {=_xlfn.XLOOKUP($C20&G$19,inTokens&outTokens,beta)} -> 0.14695438
B21: =B6 -> inTokens | C21: =C6 -> 256 | D21: {=_xlfn.XLOOKUP($C21&D$19,inTokens&outTokens,beta)} -> 0.015459432 | E21: {=_xlfn.XLOOKUP($C21&E$19,inTokens&outTokens,beta)} -> 0.025434095 | F21: {=_xlfn.XLOOKUP($C21&F$19,inTokens&outTokens,beta)} -> 0.033372936 | G21: {=_xlfn.XLOOKUP($C21&G$19,inTokens&outTokens,beta)} -> 0.049957213
C22: =C7 -> 1024 | D22: {=_xlfn.XLOOKUP($C22&D$19,inTokens&outTokens,beta)} -> 0.015826952 | E22: {=_xlfn.XLOOKUP($C22&E$19,inTokens&outTokens,beta)} -> 0.019984866 | F22: {=_xlfn.XLOOKUP($C22&F$19,inTokens&outTokens,beta)} -> 0.025064985 | G22: {=_xlfn.XLOOKUP($C22&G$19,inTokens&outTokens,beta)} -> 0.029330378
C23: =C8 -> 4096 | D23: {=_xlfn.XLOOKUP($C23&D$19,inTokens&outTokens,beta)} -> 0.021128778 | E23: {=_xlfn.XLOOKUP($C23&E$19,inTokens&outTokens,beta)} -> 0.023400079 | F23: {=_xlfn.XLOOKUP($C23&F$19,inTokens&outTokens,beta)} -> 0.025388566 | G23: {=_xlfn.XLOOKUP($C23&G$19,inTokens&outTokens,beta)} -> 0.025792132
B32: gamma
E33: =E18 -> outTokens
D34: =D19 -> 64 | E34: =E19 -> 256 | F34: =F19 -> 1024 | G34: =G19 -> 4096
C35: =C20 -> 64 | D35: {=_xlfn.XLOOKUP($C35&D$34,inTokens&outTokens,gamma)} -> 0.00014145338 | E35: {=_xlfn.XLOOKUP($C35&E$34,inTokens&outTokens,gamma)} -> 1.2762776e-05 | F35: {=_xlfn.XLOOKUP($C35&F$34,inTokens&outTokens,gamma)} -> 1.3346809e-05 | G35: {=_xlfn.XLOOKUP($C35&G$34,inTokens&outTokens,gamma)} -> 4e-12
B36: =B21 -> inTokens | C36: =C21 -> 256 | D36: {=_xlfn.XLOOKUP($C36&D$34,inTokens&outTokens,gamma)} -> 0.00012840221 | E36: {=_xlfn.XLOOKUP($C36&E$34,inTokens&outTokens,gamma)} -> 3.819576e-05 | F36: {=_xlfn.XLOOKUP($C36&F$34,inTokens&outTokens,gamma)} -> 3.5739094e-05 | G36: {=_xlfn.XLOOKUP($C36&G$34,inTokens&outTokens,gamma)} -> 4.6459862e-05
C37: =C22 -> 1024 | D37: {=_xlfn.XLOOKUP($C37&D$34,inTokens&outTokens,gamma)} -> 0.00010576153 | E37: {=_xlfn.XLOOKUP($C37&E$34,inTokens&outTokens,gamma)} -> 4.992544e-05 | F37: {=_xlfn.XLOOKUP($C37&F$34,inTokens&outTokens,gamma)} -> 4.5017178e-05 | G37: {=_xlfn.XLOOKUP($C37&G$34,inTokens&outTokens,gamma)} -> 5.6029386e-05
C38: =C23 -> 4096 | D38: {=_xlfn.XLOOKUP($C38&D$34,inTokens&outTokens,gamma)} -> 5e-12 | E38: {=_xlfn.XLOOKUP($C38&E$34,inTokens&outTokens,gamma)} -> 4.0889511e-05 | F38: {=_xlfn.XLOOKUP($C38&F$34,inTokens&outTokens,gamma)} -> 4.6007139e-05 | G38: {=_xlfn.XLOOKUP($C38&G$34,inTokens&outTokens,gamma)} -> 5.2142187e-05
R43: \
B47: avgWeightedError
E48: =E3 -> outTokens
D49: =D4 -> 64 | E49: =E4 -> 256 | F49: =F4 -> 1024 | G49: =G4 -> 4096
C50: =C5 -> 64 | D50: {=_xlfn.XLOOKUP($C50&D$49,inTokens&outTokens,avgError)} -> 0.930904 | E50: {=_xlfn.XLOOKUP($C50&E$49,inTokens&outTokens,avgError)} -> 0.991261 | F50: {=_xlfn.XLOOKUP($C50&F$49,inTokens&outTokens,avgError)} -> 1.270442 | G50: {=_xlfn.XLOOKUP($C50&G$49,inTokens&outTokens,avgError)} -> 0.847561
B51: =B6 -> inTokens | C51: =C6 -> 256 | D51: {=_xlfn.XLOOKUP($C51&D$49,inTokens&outTokens,avgError)} -> 1.259143 | E51: {=_xlfn.XLOOKUP($C51&E$49,inTokens&outTokens,avgError)} -> 0.616832 | F51: {=_xlfn.XLOOKUP($C51&F$49,inTokens&outTokens,avgError)} -> 0.513572 | G51: {=_xlfn.XLOOKUP($C51&G$49,inTokens&outTokens,avgError)} -> 0.765065
C52: =C7 -> 1024 | D52: {=_xlfn.XLOOKUP($C52&D$49,inTokens&outTokens,avgError)} -> 1.999902 | E52: {=_xlfn.XLOOKUP($C52&E$49,inTokens&outTokens,avgError)} -> 1.425539 | F52: {=_xlfn.XLOOKUP($C52&F$49,inTokens&outTokens,avgError)} -> 1.004126 | G52: {=_xlfn.XLOOKUP($C52&G$49,inTokens&outTokens,avgError)} -> 0.573291
C53: =C8 -> 4096 | D53: {=_xlfn.XLOOKUP($C53&D$49,inTokens&outTokens,avgError)} -> 3.757978 | E53: {=_xlfn.XLOOKUP($C53&E$49,inTokens&outTokens,avgError)} -> 1.804561 | F53: {=_xlfn.XLOOKUP($C53&F$49,inTokens&outTokens,avgError)} -> 1.428354 | G53: {=_xlfn.XLOOKUP($C53&G$49,inTokens&outTokens,avgError)} -> 1.184672
B62: avgTTFTError
E64: =E3 -> outTokens
D65: =D4 -> 64 | E65: =E4 -> 256 | F65: =F4 -> 1024 | G65: =G4 -> 4096
C66: =C5 -> 64 | D66: {=_xlfn.XLOOKUP($C50&D$49,inTokens&outTokens,avgTTFTError)} -> 1.237417 | E66: {=_xlfn.XLOOKUP($C50&E$49,inTokens&outTokens,avgTTFTError)} -> 2.235121 | F66: {=_xlfn.XLOOKUP($C50&F$49,inTokens&outTokens,avgTTFTError)} -> 2.226525 | G66: {=_xlfn.XLOOKUP($C50&G$49,inTokens&outTokens,avgTTFTError)} -> 2.100917
B67: =B6 -> inTokens | C67: =C6 -> 256 | D67: {=_xlfn.XLOOKUP($C51&D$49,inTokens&outTokens,avgTTFTError)} -> 2.024889 | E67: {=_xlfn.XLOOKUP($C51&E$49,inTokens&outTokens,avgTTFTError)} -> 0.826128 | F67: {=_xlfn.XLOOKUP($C51&F$49,inTokens&outTokens,avgTTFTError)} -> 0.712701 | G67: {=_xlfn.XLOOKUP($C51&G$49,inTokens&outTokens,avgTTFTError)} -> 1.628342
C68: =C7 -> 1024 | D68: {=_xlfn.XLOOKUP($C52&D$49,inTokens&outTokens,avgTTFTError)} -> 5.345906 | E68: {=_xlfn.XLOOKUP($C52&E$49,inTokens&outTokens,avgTTFTError)} -> 3.653355 | F68: {=_xlfn.XLOOKUP($C52&F$49,inTokens&outTokens,avgTTFTError)} -> 1.99104 | G68: {=_xlfn.XLOOKUP($C52&G$49,inTokens&outTokens,avgTTFTError)} -> 1.165777
C69: =C8 -> 4096 | D69: {=_xlfn.XLOOKUP($C53&D$49,inTokens&outTokens,avgTTFTError)} -> 4.283691 | E69: {=_xlfn.XLOOKUP($C53&E$49,inTokens&outTokens,avgTTFTError)} -> 4.843754 | F69: {=_xlfn.XLOOKUP($C53&F$49,inTokens&outTokens,avgTTFTError)} -> 3.566807 | G69: {=_xlfn.XLOOKUP($C53&G$49,inTokens&outTokens,avgTTFTError)} -> 3.460337
B77: avgITLError
E78: =E3 -> outTokens
D79: =D4 -> 64 | E79: =E4 -> 256 | F79: =F4 -> 1024 | G79: =G4 -> 4096
C80: =C5 -> 64 | D80: {=_xlfn.XLOOKUP($C50&D$49,inTokens&outTokens,avgITLError)} -> 0.777647 | E80: {=_xlfn.XLOOKUP($C50&E$49,inTokens&outTokens,avgITLError)} -> 0.369331 | F80: {=_xlfn.XLOOKUP($C50&F$49,inTokens&outTokens,avgITLError)} -> 0.7924 | G80: {=_xlfn.XLOOKUP($C50&G$49,inTokens&outTokens,avgITLError)} -> 0.220883
...

Sheet out
A1: sweep-i1024-o1024 | B1: Summary | C1: alpha | D1: 6.016738 | E1: beta | F1: 0.025064985 | G1: gamma | H1: 4.5017178e-05 | I1: errTTFT | J1: 1.99104 | K1: errITL | L1: 0.510669 | M1: errWeightedAvg | N1: 1.004126
A2: sweep-i1024-o256 | B2: Summary | C2: alpha | D2: 6.026902 | E2: beta | F2: 0.019984866 | G2: gamma | H2: 4.992544e-05 | I2: errTTFT | J2: 3.653355 | K2: errITL | L2: 0.31163 | M2: errWeightedAvg | N2: 1.425539
A3: sweep-i1024-o4096 | B3: Summary | C3: alpha | D3: 6.008825 | E3: beta | F3: 0.029330378 | G3: gamma | H3: 5.6029386e-05 | I3: errTTFT | J3: 1.165777 | K3: errITL | L3: 0.277047 | M3: errWeightedAvg | N3: 0.573291
A4: sweep-i1024-o64 | B4: Summary | C4: alpha | D4: 6.025469 | E4: beta | F4: 0.015826952 | G4: gamma | H4: 0.00010576153 | I4: errTTFT | J4: 5.345906 | K4: errITL | L4: 0.3269 | M4: errWeightedAvg | N4: 1.999902
A5: sweep-i256-o1024 | B5: Summary | C5: alpha | D5: 6.016668 | E5: beta | F5: 0.033372936 | G5: gamma | H5: 3.5739094e-05 | I5: errTTFT | J5: 0.712701 | K5: errITL | L5: 0.414008 | M5: errWeightedAvg | N5: 0.513572
A6: sweep-i256-o256 | B6: Summary | C6: alpha | D6: 6.014978 | E6: beta | F6: 0.025434095 | G6: gamma | H6: 3.819576e-05 | I6: errTTFT | J6: 0.826128 | K6: errITL | L6: 0.512184 | M6: errWeightedAvg | N6: 0.616832
A7: sweep-i256-o4096 | B7: Summary | C7: alpha | D7: 6.000054 | E7: beta | F7: 0.049957213 | G7: gamma | H7: 4.6459862e-05 | I7: errTTFT | J7: 1.628342 | K7: errITL | L7: 0.333426 | M7: errWeightedAvg | N7: 0.765065
A8: sweep-i256-o64 | B8: Summary | C8: alpha | D8: 6.029422 | E8: beta | F8: 0.015459432 | G8: gamma | H8: 0.00012840221 | I8: errTTFT | J8: 2.024889 | K8: errITL | L8: 0.87627 | M8: errWeightedAvg | N8: 1.259143
A9: sweep-i4096-o1024 | B9: Summary | C9: alpha | D9: 6.023934 | E9: beta | F9: 0.025388566 | G9: gamma | H9: 4.6007139e-05 | I9: errTTFT | J9: 3.566807 | K9: errITL | L9: 0.359127 | M9: errWeightedAvg | N9: 1.428354
A10: sweep-i4096-o256 | B10: Summary | C10: alpha | D10: 6.026099 | E10: beta | F10: 0.023400079 | G10: gamma | H10: 4.0889511e-05 | I10: errTTFT | J10: 4.843754 | K10: errITL | L10: 0.284965 | M10: errWeightedAvg | N10: 1.804561
A11: sweep-i4096-o4096 | B11: Summary | C11: alpha | D11: 6.023698 | E11: beta | F11: 0.025792132 | G11: gamma | H11: 5.2142187e-05 | I11: errTTFT | J11: 3.460337 | K11: errITL | L11: 0.046839 | M11: errWeightedAvg | N11: 1.184672
A12: sweep-i4096-o64 | B12: Summary | C12: alpha | D12: 6.027918 | E12: beta | F12: 0.021128778 | G12: gamma | H12: 5e-12 | I12: errTTFT | J12: 4.283691 | K12: errITL | L12: 3.495122 | M12: errWeightedAvg | N12: 3.757978
... A16: sweep-i64-o64 | B16: Summary | C16: alpha | D16: 6.027926 | E16: beta | F16: 0.022009101 | G16: gamma | H16: 0.00014145338 | I16: errTTFT | J16: 1.237417 | K16: errITL | L16: 0.777647 | M16: errWeightedAvg | N16: 0.930904

Sheet data
B3: inTokens | C3: outTokens | D3: alpha | E3: beta | F3: gamma | G3: avgTTFTError | H3: avgITLError | I3: avgError
B4: =_xlfn.TEXTBEFORE(_xlfn.TEXTAFTER(out!A1,"-i"),"-o") -> 1024 | C4: =_xlfn.TEXTAFTER(out!A1,"-o") -> 1024 | D4: =out!D1 -> 6.016738 | E4: =out!F1 -> 0.025064985 | F4: =out!H1 -> 4.5017178e-05 | G4: =out!J1 -> 1.99104 | H4: =out!L1 -> 0.510669 | I4: =out!N1 -> 1.004126
B5: =_xlfn.TEXTBEFORE(_xlfn.TEXTAFTER(out!A2,"-i"),"-o") -> 1024 | C5: =_xlfn.TEXTAFTER(out!A2,"-o") -> 256 | D5: =out!D2 -> 6.026902 | E5: =out!F2 -> 0.019984866 | F5: =out!H2 -> 4.992544e-05 | G5: =out!J2 -> 3.653355 | H5: =out!L2 -> 0.31163 | I5: =out!N2 -> 1.425539
B6: =_xlfn.TEXTBEFORE(_xlfn.TEXTAFTER(out!A3,"-i"),"-o") -> 1024 | C6: =_xlfn.TEXTAFTER(out!A3,"-o") -> 4096 | D6: =out!D3 -> 6.008825 | E6: =out!F3 -> 0.029330378 | F6: =out!H3 -> 5.6029386e-05 | G6: =out!J3 -> 1.165777 | H6: =out!L3 -> 0.277047 | I6: =out!N3 -> 0.573291
B7: =_xlfn.TEXTBEFORE(_xlfn.TEXTAFTER(out!A4,"-i"),"-o") -> 1024 | C7: =_xlfn.TEXTAFTER(out!A4,"-o") -> 64 | D7: =out!D4 -> 6.025469 | E7: =out!F4 -> 0.015826952 | F7: =out!H4 -> 0.00010576153 | G7: =out!J4 -> 5.345906 | H7: =out!L4 -> 0.3269 | I7: =out!N4 -> 1.999902
B8: =_xlfn.TEXTBEFORE(_xlfn.TEXTAFTER(out!A5,"-i"),"-o") -> 256 | C8: =_xlfn.TEXTAFTER(out!A5,"-o") -> 1024 | D8: =out!D5 -> 6.016668 | E8: =out!F5 -> 0.033372936 | F8: =out!H5 -> 3.5739094e-05 | G8: =out!J5 -> 0.712701 | H8: =out!L5 -> 0.414008 | I8: =out!N5 -> 0.513572
B9: =_xlfn.TEXTBEFORE(_xlfn.TEXTAFTER(out!A6,"-i"),"-o") -> 256 | C9: =_xlfn.TEXTAFTER(out!A6,"-o") -> 256 | D9: =out!D6 -> 6.014978 | E9: =out!F6 -> 0.025434095 | F9: =out!H6 -> 3.819576e-05 | G9: =out!J6 -> 0.826128 | H9: =out!L6 -> 0.512184 | I9: =out!N6 -> 0.616832
B10: =_xlfn.TEXTBEFORE(_xlfn.TEXTAFTER(out!A7,"-i"),"-o") -> 256 | C10: =_xlfn.TEXTAFTER(out!A7,"-o") -> 4096 | D10: =out!D7 -> 6.000054 | E10: =out!F7 -> 0.049957213 | F10: =out!H7 -> 4.6459862e-05 | G10: =out!J7 -> 1.628342 | H10: =out!L7 -> 0.333426 | I10: =out!N7 -> 0.765065
B11: =_xlfn.TEXTBEFORE(_xlfn.TEXTAFTER(out!A8,"-i"),"-o") -> 256 | C11: =_xlfn.TEXTAFTER(out!A8,"-o") -> 64 | D11: =out!D8 -> 6.029422 | E11: =out!F8 -> 0.015459432 | F11: =out!H8 -> 0.00012840221 | G11: =out!J8 -> 2.024889 | H11: =out!L8 -> 0.87627 | I11: =out!N8 -> 1.259143
B12: =_xlfn.TEXTBEFORE(_xlfn.TEXTAFTER(out!A9,"-i"),"-o") -> 4096 | C12: =_xlfn.TEXTAFTER(out!A9,"-o") -> 1024 | D12: =out!D9 -> 6.023934 | E12: =out!F9 -> 0.025388566 | F12: =out!H9 -> 4.6007139e-05 | G12: =out!J9 -> 3.566807 | H12: =out!L9 -> 0.359127 | I12: =out!N9 -> 1.428354
B13: =_xlfn.TEXTBEFORE(_xlfn.TEXTAFTER(out!A10,"-i"),"-o") -> 4096 | C13: =_xlfn.TEXTAFTER(out!A10,"-o") -> 256 | D13: =out!D10 -> 6.026099 | E13: =out!F10 -> 0.023400079 | F13: =out!H10 -> 4.0889511e-05 | G13: =out!J10 -> 4.843754 | H13: =out!L10 -> 0.284965 | I13: =out!N10 -> 1.804561
B14: =_xlfn.TEXTBEFORE(_xlfn.TEXTAFTER(out!A11,"-i"),"-o") -> 4096 | C14: =_xlfn.TEXTAFTER(out!A11,"-o") -> 4096 | D14: =out!D11 -> 6.023698 | E14: =out!F11 -> 0.025792132 | F14: =out!H11 -> 5.2142187e-05 | G14: =out!J11 -> 3.460337 | H14: =out!L11 -> 0.046839 | I14: =out!N11 -> 1.184672
B15: =_xlfn.TEXTBEFORE(_xlfn.TEXTAFTER(out!A12,"-i"),"-o") -> 4096 | C15: =_xlfn.TEXTAFTER(out!A12,"-o") -> 64 | D15: =out!D12 -> 6.027918 | E15: =out!F12 -> 0.021128778 | F15: =out!H12 -> 5e-12 | G15: =out!J12 -> 4.283691 | H15: =out!L12 -> 3.495122 | I15: =out!N12 -> 3.757978
... B19: =_xlfn.TEXTBEFORE(_xlfn.TEXTAFTER(out!A16,"-i"),"-o") -> 64 | C19: =_xlfn.TEXTAFTER(out!A16,"-o") -> 64 | D19: =out!D16 -> 6.027926 | E19: =out!F16 -> 0.022009101 | F19: =out!H16 -> 0.00014145338 | G19: =out!J16 -> 1.237417 | H19: =out!L16 -> 0.777647 | I19: =out!N16 -> 0.930904
